from __future__ import annotations

import voluptuous as vol
from homeassistant import config_entries
from homeassistant.core import HomeAssistant
from homeassistant.data_entry_flow import FlowResult
from homeassistant.exceptions import HomeAssistantError

from .const import DOMAIN
from .firststreet_api import FirstStreetAPI, FirstStreetAPIError

STEP_USER_DATA_SCHEMA = vol.Schema(
    {
        vol.Required("fsid"): int,
        vol.Optional("building_id", default=0): int,
    }
)

async def validate_input(hass: HomeAssistant, data: dict[str, Any]) -> dict[str, Any]:
    """Validate the user input allows us to connect."""
    api = FirstStreetAPI()

    try:
        await hass.async_add_executor_job(api.get_all_risk_data, data["fsid"], data["building_id"])
    except FirstStreetAPIError as err:
        raise InvalidAuth from err

    return {"title": f"Property {data['fsid']}"}

class ConfigFlow(config_entries.ConfigFlow, domain=DOMAIN):
    """Handle a config flow for FirstStreet."""

    VERSION = 1

    async def async_step_user(
        self, user_input: dict[str, Any] | None = None
    ) -> FlowResult:
        """Handle the initial step."""
        errors: dict[str, str] = {}
        if user_input is None:
            return self.async_show_form(
                step_id="user", data_schema=STEP_USER_DATA_SCHEMA
            )

        try:
            info = await validate_input(self.hass, user_input)
        except CannotConnect:
            errors["base"] = "cannot_connect"
        except InvalidAuth:
            errors["base"] = "invalid_auth"
        except Exception:  # pylint: disable=broad-except
            errors["base"] = "unknown"
        else:
            return self.async_create_entry(title=info["title"], data=user_input)

        return self.async_show_form(
            step_id="user", data_schema=STEP_USER_DATA_SCHEMA, errors=errors
        )

class CannotConnect(HomeAssistantError):
    """Error to indicate we cannot connect."""

class InvalidAuth(HomeAssistantError):
    """Error to indicate there is invalid auth."""
